<?xml version="1.0" ?>
<!-- =================================================================================== -->
<!-- |    This document was autogenerated by xacro from model.xacro                    | -->
<!-- |    EDITING THIS FILE BY HAND IS NOT RECOMMENDED                                 | -->
<!-- =================================================================================== -->
<robot name="2wheel_drive_car">
    <!-- car body -->
    <!-- <link name="car_body__link"/> -->
    <material name="car_body_color">
        <color rgba="0.97 0.25 0.25 1"/>
    </material>
    <gazebo reference="car_body">
        <material>
            <diffuse> 0.97 0.25 0.25 1 </diffuse>
            <specular> 0.2 0.2 0.2 1  </specular>
            <emissive> 0 0 0 1 </emissive>
            <ambient> 0.35 0.15 0.15 1 </ambient>
        </material>
    </gazebo>
    <link name="car_body">
        <inertial>
            <mass value="10"/>
            <origin rpy="0 0 0" xyz="0 0 0"/>
            <inertia ixx="0.5208333333333334" ixy="0" ixz="0" iyy="1.7708333333333335" iyz="0" izz="2.0833333333333335"/>
        </inertial>
        <visual>
            <geometry>
                <box size="2 1 0.5"/>
            </geometry>
            <material name="car_body_color"/>
        </visual>
        <collision>
            <geometry>
                <box size="2 1 0.5"/>
            </geometry>
        </collision>
    </link>
    <material name="car_ball_wheel_width">
        <color rgba="0.3 0.3 0.3 1"/>
    </material>
    <gazebo reference="rear_left_ball_wheel">
        <material>
            <diffuse> 0.3 0.3 0.3 1 </diffuse>
            <specular> 0 0.2 0.2 1  </specular>
            <emissive> 0 0 0 1 </emissive>
            <ambient> 0.1 0.1 0.1 1 </ambient>
        </material>
    </gazebo>
    <link name="rear_left_ball_wheel">
        <inertial>
            <mass value="0.5"/>
            <inertia ixx="0.003125" ixy="0.0" ixz="0.0" iyy="0.003125" iyz="0.0" izz="0.003125"/>
        </inertial>
        <visual>
            <geometry>
                <sphere radius="0.125"/>
            </geometry>
            <material name="car_ball_wheel_width"/>
        </visual>
        <collision>
            <geometry>
                <sphere radius="0.125"/>
            </geometry>
        </collision>
    </link>
    <joint name="rear_left_ball_wheel_to_body" type="continuous">
        <origin rpy="0.0 0.0 0.0" xyz="-0.6 0.3 -0.25"/>
        <parent link="car_body"/>
        <child link="rear_left_ball_wheel"/>
        <axis xyz="0 1 0"/>
        <dynamics friction="0.5"/>
    </joint>
    <gazebo reference="rear_right_ball_wheel">
        <material>
            <diffuse> 0.3 0.3 0.3 1 </diffuse>
            <specular> 0 0.2 0.2 1  </specular>
            <emissive> 0 0 0 1 </emissive>
            <ambient> 0.1 0.1 0.1 1 </ambient>
        </material>
    </gazebo>
    <link name="rear_right_ball_wheel">
        <inertial>
            <mass value="0.5"/>
            <inertia ixx="0.003125" ixy="0.0" ixz="0.0" iyy="0.003125" iyz="0.0" izz="0.003125"/>
        </inertial>
        <visual>
            <geometry>
                <sphere radius="0.125"/>
            </geometry>
            <material name="car_ball_wheel_width"/>
        </visual>
        <collision>
            <geometry>
                <sphere radius="0.125"/>
            </geometry>
        </collision>
    </link>
    <joint name="rear_right_ball_wheel_to_body" type="continuous">
        <origin rpy="0.0 0.0 0.0" xyz="-0.6 -0.3 -0.25"/>
        <parent link="car_body"/>
        <child link="rear_right_ball_wheel"/>
        <axis xyz="0 1 0"/>
        <dynamics friction="0.5"/>
    </joint>
    <!-- base footprint location -->
    <link name="base_footprint"/>
    <joint name="base_link" type="fixed">
        <parent link="base_footprint"/>
        <child link="car_body"/>
        <!-- <child link="base_footprint"/> -->
        <origin rpy="0 0 0" xyz="0 0 0.375"/>
    </joint>
    <material name="car_wheel_color">
        <color rgba="0.3 0.3 0.3 1"/>
    </material>
    <gazebo reference="front_left_wheel">
        <material>
            <diffuse> 0.3 0.3 0.3 1 </diffuse>
            <specular> 0 0.2 0.2 1  </specular>
            <emissive> 0 0 0 1 </emissive>
            <ambient> 0.1 0.1 0.1 1 </ambient>
        </material>
    </gazebo>
    <link name="front_left_wheel">
        <inertial>
            <mass value="0.5"/>
            <inertia ixx="0.008229166666666666" ixy="0" ixz="0" iyy="0.008229166666666666" iyz="0" izz="0.015625"/>
        </inertial>
        <collision>
            <geometry>
                <cylinder length="0.1" radius="0.25"/>
            </geometry>
        </collision>
        <visual>
            <geometry>
                <cylinder length="0.1" radius="0.25"/>
            </geometry>
            <material name="car_wheel_color"/>
        </visual>
    </link>
    <joint name="front_left_wheel_to_body" type="continuous">
        <origin rpy="-1.5707963267948966 0 0" xyz="0.6 0.5 -0.125"/>
        <parent link="car_body"/>
        <child link="front_left_wheel"/>
        <axis xyz="0 0 1"/>
        <dynamics friction="0.5"/>
    </joint>
    <gazebo reference="front_right_wheel">
        <material>
            <diffuse> 0.3 0.3 0.3 1 </diffuse>
            <specular> 0 0.2 0.2 1  </specular>
            <emissive> 0 0 0 1 </emissive>
            <ambient> 0.1 0.1 0.1 1 </ambient>
        </material>
    </gazebo>
    <link name="front_right_wheel">
        <inertial>
            <mass value="0.5"/>
            <inertia ixx="0.008229166666666666" ixy="0" ixz="0" iyy="0.008229166666666666" iyz="0" izz="0.015625"/>
        </inertial>
        <collision>
            <geometry>
                <cylinder length="0.1" radius="0.25"/>
            </geometry>
        </collision>
        <visual>
            <geometry>
                <cylinder length="0.1" radius="0.25"/>
            </geometry>
            <material name="car_wheel_color"/>
        </visual>
    </link>
    <joint name="front_right_wheel_to_body" type="continuous">
        <origin rpy="-1.5707963267948966 0 0" xyz="0.6 -0.5 -0.125"/>
        <parent link="car_body"/>
        <child link="front_right_wheel"/>
        <axis xyz="0 0 1"/>
        <dynamics friction="0.5"/>
    </joint>
    <material name="camera_color">
        <color rgba="0.52 0.8 0.98 1"/>
    </material>
    <gazebo reference="car_camera">
        <material>
            <diffuse> 0.52 0.8 0.98 1 </diffuse>
            <specular> 0.2 0.2 0.2 0  </specular>
            <emissive> 0 0 0 1 </emissive>
            <ambient> 0.114 0.16 0.196 1 </ambient>
        </material>
    </gazebo>
    <link name="car_camera">
        <inertial>
            <mass value="0.1"/>
            <origin rpy="0 0 0" xyz="0 0 0"/>
            <inertia ixx="0.000166667" ixy="0" ixz="0" iyy="0.000166667" iyz="0" izz="0.000166667"/>
        </inertial>
        <collision>
            <origin rpy="0 0 3.14" xyz="0 0 0"/>
            <geometry>
                <box size="0.1 0.1 0.1"/>
            </geometry>
        </collision>
        <visual>
            <origin rpy="0 0 3.14" xyz="0 0 0"/>
            <geometry>
                <box size="0.1 0.1 0.1"/>
            </geometry>
            <material name="camera_color"/>
        </visual>
    </link>
    <gazebo reference="car_camera">
        <sensor name="car_camera" type="camera">
            <update_rate>24</update_rate>
            <visualize>true</visualize>
            <topic>camera</topic>
            <camera name="head">
                <horizontal_fov>1.3962634</horizontal_fov>
                <image>
                    <width>640</width>
                    <height>480</height>
                    <format>R8G8B8</format>
                </image>
                <clip>
                    <near>0.02</near>
                    <far>300</far>
                </clip>
            </camera>
        </sensor>
    </gazebo>
    <joint name="camera_to_body" type="fixed">
        <origin rpy="0 0 0" xyz="0.95 0 0.3"/>
        <parent link="car_body"/>
        <child link="car_camera"/>
    </joint>
    <gazebo>
        <plugin filename="ignition-gazebo-diff-drive-system" name="ignition::gazebo::systems::DiffDrive">
            <left_joint>front_left_wheel_to_body</left_joint>
            <right_joint>front_right_wheel_to_body</right_joint>
            <wheel_separation>1</wheel_separation>
            <wheel_radius>0.25</wheel_radius>
            <odom_publish_frequency>1</odom_publish_frequency>
            <max_linear_acceleration>1</max_linear_acceleration>
            <min_linear_acceleration>-1</min_linear_acceleration>
            <max_angular_acceleration>2</max_angular_acceleration>
            <min_angular_acceleration>-2</min_angular_acceleration>
            <max_linear_velocity>0.5</max_linear_velocity>
            <min_linear_velocity>-0.5</min_linear_velocity>
            <max_angular_velocity>1</max_angular_velocity>
            <min_angular_velocity>-1</min_angular_velocity>
        </plugin>
        <plugin filename="libignition-gazebo-joint-state-publisher-system.so" name="ignition::gazebo::systems::JointStatePublisher ">
        </plugin>
    </gazebo>
</robot>
