<?xml version="1.0" ?>
<sdf version='1.7'>
    <model name='2wheel_drive_car'>
        <link name='car_body::link'>
            <inertial>
                <pose>0.009406 0 0.00297 0 -0 0</pose>
                <mass>10.1</mass>
                <inertia>
                    <ixx>0.529911</ixx>
                    <ixy>0</ixy>
                    <ixz>-0.0282178</ixz>
                    <iyy>1.86927</iyy>
                    <iyz>0</iyz>
                    <izz>2.17286</izz>
                </inertia>
            </inertial>
            <collision name='car_body::link_fixed_joint_lump__car_body_collision'>
                <pose>0 0 0 0 -0 0</pose>
                <geometry>
                    <box>
                        <size>2 1 0.5</size>
                    </box>
                </geometry>
                <surface>
                    <contact>
                        <ode/>
                    </contact>
                    <friction>
                        <ode/>
                    </friction>
                </surface>
            </collision>
            <collision name='car_body::link_fixed_joint_lump__car_camera_collision_1'>
                <pose>0.95 0 0.3 0 -0 3.14</pose>
                <geometry>
                    <box>
                        <size>0.1 0.1 0.1</size>
                    </box>
                </geometry>
                <surface>
                    <contact>
                        <ode/>
                    </contact>
                    <friction>
                        <ode/>
                    </friction>
                </surface>
            </collision>
            <visual name='car_body::link_fixed_joint_lump__car_body_visual'>
                <pose>0 0 0 0 -0 0</pose>
                <geometry>
                    <box>
                        <size>2 1 0.5</size>
                    </box>
                </geometry>
                <material>
                    <script>
                        <name>diffuse</name>
                        <uri>file://media/materials/scripts/gazebo.material</uri>
                    </script>
                </material>
            </visual>
            <visual name='car_body::link_fixed_joint_lump__car_camera_visual_1'>
                <pose>0.95 0 0.3 0 -0 3.14</pose>
                <geometry>
                    <box>
                        <size>0.1 0.1 0.1</size>
                    </box>
                </geometry>
                <material>
                    <script>
                        <name>diffuse</name>
                        <uri>file://media/materials/scripts/gazebo.material</uri>
                    </script>
                </material>
            </visual>
            <sensor name='car_camera' type='camera'>
                <update_rate>24</update_rate>
                <visualize>1</visualize>
                <camera name='head'>
                    <horizontal_fov>1.39626</horizontal_fov>
                    <image>
                        <width>640</width>
                        <height>480</height>
                        <format>R8G8B8</format>
                    </image>
                    <clip>
                        <near>0.02</near>
                        <far>300</far>
                    </clip>
                </camera>
                <plugin name='camera_controller' filename='libgazebo_ros_camera.so'>
                    <ros>
                        <argument>--ros-args --remap image_raw:=image_raw</argument>
                        <argument>--ros-args --remap camera_info:=camera_info</argument>
                    </ros>
                </plugin>
                <pose>0.95 0 0.3 0 -0 0</pose>
            </sensor>
        </link>
        <joint name='front_left_wheel_2_body' type='revolute'>
            <pose relative_to='car_body::link'>0.6 0.5 -0.125 -1.5708 0 0</pose>
            <parent>car_body::link</parent>
            <child>front_left_wheel</child>
            <axis>
                <xyz>0 0 1</xyz>
                <limit>
                    <lower>-1e+16</lower>
                    <upper>1e+16</upper>
                </limit>
                <dynamics>
                    <damping>0</damping>
                    <friction>0.5</friction>
                    <spring_reference>0</spring_reference>
                    <spring_stiffness>0</spring_stiffness>
                </dynamics>
            </axis>
        </joint>
        <link name='front_left_wheel'>
            <pose relative_to='front_left_wheel_2_body'>0 0 0 0 -0 0</pose>
            <inertial>
                <pose>0 0 0 0 -0 0</pose>
                <mass>0.5</mass>
                <inertia>
                    <ixx>0.00822917</ixx>
                    <ixy>0</ixy>
                    <ixz>0</ixz>
                    <iyy>0.00822917</iyy>
                    <iyz>0</iyz>
                    <izz>0.015625</izz>
                </inertia>
            </inertial>
            <collision name='front_left_wheel_collision'>
                <pose>0 0 0 0 -0 0</pose>
                <geometry>
                    <cylinder>
                        <length>0.1</length>
                        <radius>0.25</radius>
                    </cylinder>
                </geometry>
                <surface>
                    <contact>
                        <ode/>
                    </contact>
                    <friction>
                        <ode/>
                    </friction>
                </surface>
            </collision>
            <visual name='front_left_wheel_visual'>
                <pose>0 0 0 0 -0 0</pose>
                <geometry>
                    <cylinder>
                        <length>0.1</length>
                        <radius>0.25</radius>
                    </cylinder>
                </geometry>
                <material>
                    <script>
                        <name>diffuse</name>
                        <uri>file://media/materials/scripts/gazebo.material</uri>
                    </script>
                </material>
            </visual>
        </link>
        <joint name='front_right_wheel_2_body' type='revolute'>
            <pose relative_to='car_body::link'>0.6 -0.5 -0.125 -1.5708 0 0</pose>
            <parent>car_body::link</parent>
            <child>front_right_wheel</child>
            <axis>
                <xyz>0 0 1</xyz>
                <limit>
                    <lower>-1e+16</lower>
                    <upper>1e+16</upper>
                </limit>
                <dynamics>
                    <damping>0</damping>
                    <friction>0.5</friction>
                    <spring_reference>0</spring_reference>
                    <spring_stiffness>0</spring_stiffness>
                </dynamics>
            </axis>
        </joint>
        <link name='front_right_wheel'>
            <pose relative_to='front_right_wheel_2_body'>0 0 0 0 -0 0</pose>
            <inertial>
                <pose>0 0 0 0 -0 0</pose>
                <mass>0.5</mass>
                <inertia>
                    <ixx>0.00822917</ixx>
                    <ixy>0</ixy>
                    <ixz>0</ixz>
                    <iyy>0.00822917</iyy>
                    <iyz>0</iyz>
                    <izz>0.015625</izz>
                </inertia>
            </inertial>
            <collision name='front_right_wheel_collision'>
                <pose>0 0 0 0 -0 0</pose>
                <geometry>
                    <cylinder>
                        <length>0.1</length>
                        <radius>0.25</radius>
                    </cylinder>
                </geometry>
                <surface>
                    <contact>
                        <ode/>
                    </contact>
                    <friction>
                        <ode/>
                    </friction>
                </surface>
            </collision>
            <visual name='front_right_wheel_visual'>
                <pose>0 0 0 0 -0 0</pose>
                <geometry>
                    <cylinder>
                        <length>0.1</length>
                        <radius>0.25</radius>
                    </cylinder>
                </geometry>
                <material>
                    <script>
                        <name>diffuse</name>
                        <uri>file://media/materials/scripts/gazebo.material</uri>
                    </script>
                </material>
            </visual>
        </link>
        <joint name='rear_left_ball_wheel_2_body' type='revolute'>
            <pose relative_to='car_body::link'>-0.6 0.3 -0.25 0 -0 0</pose>
            <parent>car_body::link</parent>
            <child>rear_left_ball_wheel</child>
            <axis>
                <xyz>0 1 0</xyz>
                <limit>
                    <lower>-1e+16</lower>
                    <upper>1e+16</upper>
                </limit>
                <dynamics>
                    <damping>0</damping>
                    <friction>0.5</friction>
                    <spring_reference>0</spring_reference>
                    <spring_stiffness>0</spring_stiffness>
                </dynamics>
            </axis>
        </joint>
        <link name='rear_left_ball_wheel'>
            <pose relative_to='rear_left_ball_wheel_2_body'>0 0 0 0 -0 0</pose>
            <inertial>
                <pose>0 0 0 0 -0 0</pose>
                <mass>0.5</mass>
                <inertia>
                    <ixx>0.003125</ixx>
                    <ixy>0</ixy>
                    <ixz>0</ixz>
                    <iyy>0.003125</iyy>
                    <iyz>0</iyz>
                    <izz>0.003125</izz>
                </inertia>
            </inertial>
            <collision name='rear_left_ball_wheel_collision'>
                <pose>0 0 0 0 -0 0</pose>
                <geometry>
                    <sphere>
                        <radius>0.125</radius>
                    </sphere>
                </geometry>
                <surface>
                    <contact>
                        <ode/>
                    </contact>
                    <friction>
                        <ode/>
                    </friction>
                </surface>
            </collision>
            <visual name='rear_left_ball_wheel_visual'>
                <pose>0 0 0 0 -0 0</pose>
                <geometry>
                    <sphere>
                        <radius>0.125</radius>
                    </sphere>
                </geometry>
                <material>
                    <script>
                        <name>diffuse</name>
                        <uri>file://media/materials/scripts/gazebo.material</uri>
                    </script>
                </material>
            </visual>
        </link>
        <joint name='rear_right_ball_wheel_2_body' type='revolute'>
            <pose relative_to='car_body::link'>-0.6 -0.3 -0.25 0 -0 0</pose>
            <parent>car_body::link</parent>
            <child>rear_right_ball_wheel</child>
            <axis>
                <xyz>0 1 0</xyz>
                <limit>
                    <lower>-1e+16</lower>
                    <upper>1e+16</upper>
                </limit>
                <dynamics>
                    <damping>0</damping>
                    <friction>0.5</friction>
                    <spring_reference>0</spring_reference>
                    <spring_stiffness>0</spring_stiffness>
                </dynamics>
            </axis>
        </joint>
        <link name='rear_right_ball_wheel'>
            <pose relative_to='rear_right_ball_wheel_2_body'>0 0 0 0 -0 0</pose>
            <inertial>
                <pose>0 0 0 0 -0 0</pose>
                <mass>0.5</mass>
                <inertia>
                    <ixx>0.003125</ixx>
                    <ixy>0</ixy>
                    <ixz>0</ixz>
                    <iyy>0.003125</iyy>
                    <iyz>0</iyz>
                    <izz>0.003125</izz>
                </inertia>
            </inertial>
            <collision name='rear_right_ball_wheel_collision'>
                <pose>0 0 0 0 -0 0</pose>
                <geometry>
                    <sphere>
                        <radius>0.125</radius>
                    </sphere>
                </geometry>
                <surface>
                    <contact>
                        <ode/>
                    </contact>
                    <friction>
                        <ode/>
                    </friction>
                </surface>
            </collision>
            <visual name='rear_right_ball_wheel_visual'>
                <pose>0 0 0 0 -0 0</pose>
                <geometry>
                    <sphere>
                        <radius>0.125</radius>
                    </sphere>
                </geometry>
                <material>
                    <script>
                        <name>diffuse</name>
                        <uri>file://media/materials/scripts/gazebo.material</uri>
                    </script>
                </material>
            </visual>
        </link>
        <static>0</static>
        <plugin name='two_wheeled_robot_diff_drive' filename='libgazebo_ros_diff_drive.so'>
            <num_wheel_pairs>1</num_wheel_pairs>
            <left_joint>front_left_wheel_2_body</left_joint>
            <right_joint>front_right_wheel_2_body</right_joint>
            <wheel_separation>1</wheel_separation>
            <wheel_diameter>0.5</wheel_diameter>
            <max_wheel_torque>20</max_wheel_torque>
            <publish_odom>1</publish_odom>
            <publish_odom_tf>1</publish_odom_tf>
            <odometry_frame>start_loc_map</odometry_frame>
            <robot_base_frame>car_body::link</robot_base_frame>
        </plugin>
    </model>
</sdf>
