<?xml version="1.0" ?>
<!-- =================================================================================== -->
<!-- |    This document was autogenerated by xacro from model.xacro                    | -->
<!-- |    EDITING THIS FILE BY HAND IS NOT RECOMMENDED                                 | -->
<!-- =================================================================================== -->
<robot name="2wheel_drive_car">
    <!-- car body -->
    <link name="car_body::link"/>
    <material name="car_body_color">
        <color rgba="0.97 0.25 0.25 1"/>
    </material>
    <gazebo reference="car_body">
        <material>
            <diffuse> 0.97 0.25 0.25 1 </diffuse>
            <specular> 0.2 0.2 0.2 1  </specular>
            <emissive> 0 0 0 1 </emissive>
            <ambient> 0.35 0.15 0.15 1 </ambient>
        </material>
    </gazebo>
    <link name="car_body">
        <inertial>
            <mass value="10"/>
            <origin rpy="0 0 0" xyz="0 0 0"/>
            <inertia ixx="0.5208333333333334" ixy="0" ixz="0" iyy="1.7708333333333335" iyz="0" izz="2.0833333333333335"/>
        </inertial>
        <visual>
            <geometry>
                <box size="2 1 0.5"/>
            </geometry>
            <material name="car_body_color"/>
        </visual>
        <collision>
            <geometry>
                <box size="2 1 0.5"/>
            </geometry>
        </collision>
    </link>
    <joint name="carbodylink_2_carbody" type="fixed">
        <parent link="car_body::link"/>
        <child link="car_body"/>
    </joint>
    <material name="car_ball_wheel_width">
        <color rgba="0.3 0.3 0.3 1"/>
    </material>
    <gazebo reference="rear_left_ball_wheel">
        <material>
            <diffuse> 0.3 0.3 0.3 1 </diffuse>
            <specular> 0 0.2 0.2 1  </specular>
            <emissive> 0 0 0 1 </emissive>
            <ambient> 0.1 0.1 0.1 1 </ambient>
        </material>
    </gazebo>
    <link name="rear_left_ball_wheel">
        <inertial>
            <mass value="0.5"/>
            <inertia ixx="0.003125" ixy="0.0" ixz="0.0" iyy="0.003125" iyz="0.0" izz="0.003125"/>
        </inertial>
        <visual>
            <geometry>
                <sphere radius="0.125"/>
            </geometry>
            <material name="car_ball_wheel_width"/>
        </visual>
        <collision>
            <geometry>
                <sphere radius="0.125"/>
            </geometry>
        </collision>
    </link>
    <joint name="rear_left_ball_wheel_2_body" type="continuous">
        <origin rpy="0.0 0.0 0.0" xyz="-0.6 0.3 -0.25"/>
        <parent link="car_body"/>
        <child link="rear_left_ball_wheel"/>
        <axis xyz="0 1 0"/>
        <dynamics friction="0.5"/>
    </joint>
    <gazebo reference="rear_right_ball_wheel">
        <material>
            <diffuse> 0.3 0.3 0.3 1 </diffuse>
            <specular> 0 0.2 0.2 1  </specular>
            <emissive> 0 0 0 1 </emissive>
            <ambient> 0.1 0.1 0.1 1 </ambient>
        </material>
    </gazebo>
    <link name="rear_right_ball_wheel">
        <inertial>
            <mass value="0.5"/>
            <inertia ixx="0.003125" ixy="0.0" ixz="0.0" iyy="0.003125" iyz="0.0" izz="0.003125"/>
        </inertial>
        <visual>
            <geometry>
                <sphere radius="0.125"/>
            </geometry>
            <material name="car_ball_wheel_width"/>
        </visual>
        <collision>
            <geometry>
                <sphere radius="0.125"/>
            </geometry>
        </collision>
    </link>
    <joint name="rear_right_ball_wheel_2_body" type="continuous">
        <origin rpy="0.0 0.0 0.0" xyz="-0.6 -0.3 -0.25"/>
        <parent link="car_body"/>
        <child link="rear_right_ball_wheel"/>
        <axis xyz="0 1 0"/>
        <dynamics friction="0.5"/>
    </joint>
    <!-- base footprint location -->
    <link name="base_footprint"/>
    <joint name="base_link" type="fixed">
        <parent link="car_body"/>
        <child link="base_footprint"/>
        <origin rpy="0 0 0" xyz="0 0 -0.375"/>
    </joint>
    <material name="car_wheel_color">
        <color rgba="0.3 0.3 0.3 1"/>
    </material>
    <gazebo reference="front_left_wheel">
        <material>
            <diffuse> 0.3 0.3 0.3 1 </diffuse>
            <specular> 0 0.2 0.2 1  </specular>
            <emissive> 0 0 0 1 </emissive>
            <ambient> 0.1 0.1 0.1 1 </ambient>
        </material>
    </gazebo>
    <link name="front_left_wheel">
        <inertial>
            <mass value="0.5"/>
            <inertia ixx="0.008229166666666666" ixy="0" ixz="0" iyy="0.008229166666666666" iyz="0" izz="0.015625"/>
        </inertial>
        <collision>
            <geometry>
                <cylinder length="0.1" radius="0.25"/>
            </geometry>
        </collision>
        <visual>
            <geometry>
                <cylinder length="0.1" radius="0.25"/>
            </geometry>
            <material name="car_wheel_color"/>
        </visual>
    </link>
    <joint name="front_left_wheel_2_body" type="continuous">
        <origin rpy="-1.5707963267948966 0 0" xyz="0.6 0.5 -0.125"/>
        <parent link="car_body"/>
        <child link="front_left_wheel"/>
        <axis xyz="0 0 1"/>
        <dynamics friction="0.5"/>
    </joint>
    <gazebo reference="front_right_wheel">
        <material>
            <diffuse> 0.3 0.3 0.3 1 </diffuse>
            <specular> 0 0.2 0.2 1  </specular>
            <emissive> 0 0 0 1 </emissive>
            <ambient> 0.1 0.1 0.1 1 </ambient>
        </material>
    </gazebo>
    <link name="front_right_wheel">
        <inertial>
            <mass value="0.5"/>
            <inertia ixx="0.008229166666666666" ixy="0" ixz="0" iyy="0.008229166666666666" iyz="0" izz="0.015625"/>
        </inertial>
        <collision>
            <geometry>
                <cylinder length="0.1" radius="0.25"/>
            </geometry>
        </collision>
        <visual>
            <geometry>
                <cylinder length="0.1" radius="0.25"/>
            </geometry>
            <material name="car_wheel_color"/>
        </visual>
    </link>
    <joint name="front_right_wheel_2_body" type="continuous">
        <origin rpy="-1.5707963267948966 0 0" xyz="0.6 -0.5 -0.125"/>
        <parent link="car_body"/>
        <child link="front_right_wheel"/>
        <axis xyz="0 0 1"/>
        <dynamics friction="0.5"/>
    </joint>
    <material name="camera_color">
        <color rgba="0.52 0.8 0.98 1"/>
    </material>
    <gazebo reference="camera_ros">
        <material>
            <diffuse> 0.52 0.8 0.98 1 </diffuse>
            <specular> 0.2 0.2 0.2 0  </specular>
            <emissive> 0 0 0 1 </emissive>
            <ambient> 0.114 0.16 0.196 1 </ambient>
        </material>
    </gazebo>
    <link name="camera_ros">
        <inertial>
            <mass value="0.1"/>
            <origin rpy="0 0 0" xyz="0 0 0"/>
            <inertia ixx="0.000166667" ixy="0" ixz="0" iyy="0.000166667" iyz="0" izz="0.000166667"/>
        </inertial>
        <collision>
            <origin rpy="0 0 3.14" xyz="0 0 0"/>
            <geometry>
                <box size="0.1 0.1 0.1"/>
            </geometry>
        </collision>
        <visual>
            <origin rpy="0 0 3.14" xyz="0 0 0"/>
            <geometry>
                <box size="0.1 0.1 0.1"/>
            </geometry>
            <material name="camera_color"/>
        </visual>
    </link>
    <joint name="camera_2_body" type="fixed">
        <origin rpy="0 0 0" xyz="0.95 0 0.3"/>
        <parent link="car_body"/>
        <child link="camera_ros"/>
    </joint>
    <gazebo>
        <plugin filename="libgazebo_ros_diff_drive.so" name="two_wheeled_robot_diff_drive">
            <!-- Number of wheel pairs -->
            <num_wheel_pairs>1</num_wheel_pairs>
            <!-- wheels0 -->
            <left_joint>front_left_wheel_2_body</left_joint>
            <right_joint>front_right_wheel_2_body</right_joint>
            <!-- kinematics -->
            <wheel_separation>1</wheel_separation>
            <wheel_diameter>0.5</wheel_diameter>
            <!-- limits -->
            <max_wheel_torque>20</max_wheel_torque>
            <!-- <max_wheel_acceleration>5.0</max_wheel_acceleration> -->
            <!-- output -->
            <publish_odom>true</publish_odom>
            <publish_odom_tf>true</publish_odom_tf>
            <!-- <publish_wheel_tf>true</publish_wheel_tf> -->
            <!-- <ros><argument>cmd_vel:=custom_cmd_vel</argument></ros> -->
            <odometry_frame>start_loc_map</odometry_frame>
            <robot_base_frame>car_body::link</robot_base_frame>
        </plugin>
    </gazebo>
</robot>
