<?xml version="1.0" ?>
<sdf version='1.7'>
    <model name='two_wheel_drive_car'>
        <!-- <model name='vehicle_blue'> -->
        <link name='car_body__link'>
            <inertial>
                <pose>0.009406 0 0.00297 0 -0 0</pose>
                <mass>10.1</mass>
                <inertia>
                    <ixx>0.529911</ixx>
                    <ixy>0</ixy>
                    <ixz>-0.0282178</ixz>
                    <iyy>1.86927</iyy>
                    <iyz>0</iyz>
                    <izz>2.17286</izz>
                </inertia>
            </inertial>
            <collision name='car_body__link_fixed_joint_lump__car_body_collision'>
                <pose>0 0 0 0 -0 0</pose>
                <geometry>
                    <box>
                        <size>2 1 0.5</size>
                    </box>
                </geometry>
                <surface>
                    <contact>
                        <ode/>
                    </contact>
                    <friction>
                        <ode/>
                    </friction>
                </surface>
            </collision>
            <collision name='car_body__link_fixed_joint_lump__car_camera_collision_1'>
                <pose>0.95 0 0.3 0 -0 3.14</pose>
                <geometry>
                    <box>
                        <size>0.1 0.1 0.1</size>
                    </box>
                </geometry>
                <surface>
                    <contact>
                        <ode/>
                    </contact>
                    <friction>
                        <ode/>
                    </friction>
                </surface>
            </collision>
            <visual name='car_body__link_fixed_joint_lump__car_body_visual'>
                <pose>0 0 0 0 -0 0</pose>
                <geometry>
                    <box>
                        <size>2 1 0.5</size>
                    </box>
                </geometry>
                <material>
                    <diffuse> 0.97 0.25 0.25 1 </diffuse>
                    <specular> 0.2 0.2 0.2 1  </specular>
                    <emissive> 0 0 0 1 </emissive>
                    <ambient> 0.35 0.15 0.15 1 </ambient>
                </material>
            </visual>
            <visual name='car_body__link_fixed_joint_lump__car_camera_visual_1'>
                <pose>0.95 0 0.3 0 -0 3.14</pose>
                <geometry>
                    <box>
                        <size>0.1 0.1 0.1</size>
                    </box>
                </geometry>
                <material>
                    <diffuse> 0.52 0.8 0.98 1 </diffuse>
                    <specular> 0.2 0.2 0.2 0  </specular>
                    <emissive> 0 0 0 1 </emissive>
                    <ambient> 0.114 0.16 0.196 1 </ambient>
                </material>
            </visual>
            <sensor name='car_camera' type='camera'>
                <update_rate>24</update_rate>
                <visualize>1</visualize>
                <topic>camera</topic>
                <camera name='head'>
                    <horizontal_fov>1.39626</horizontal_fov>
                    <image>
                        <width>640</width>
                        <height>480</height>
                        <format>R8G8B8</format>
                    </image>
                    <clip>
                        <near>0.02</near>
                        <far>300</far>
                    </clip>
                </camera>
                <pose>0.95 0 0.3 0 -0 0</pose>
            </sensor>
        </link>
        <joint name='front_left_wheel_to_body' type='revolute'>
            <!-- <joint name='left_wheel_joint' type="revolute"> -->
            <pose relative_to='car_body__link'>0.6 0.5 -0.125 -1.5708 0 0</pose>
            <parent>car_body__link</parent>
            <child>front_left_wheel</child>
            <axis>
                <xyz>0 0 1</xyz>
                <limit>
                    <lower>-1e+16</lower>
                    <upper>1e+16</upper>
                </limit>
                <dynamics>
                    <damping>0</damping>
                    <friction>0.5</friction>
                    <spring_reference>0</spring_reference>
                    <spring_stiffness>0</spring_stiffness>
                </dynamics>
            </axis>
        </joint>
        <link name='front_left_wheel'>
            <pose relative_to='front_left_wheel_to_body'>0 0 0 0 -0 0</pose>
            <!-- <pose relative_to='left_wheel_joint'>0 0 0 0 -0 0</pose> -->
            <inertial>
                <pose>0 0 0 0 -0 0</pose>
                <mass>0.5</mass>
                <inertia>
                    <ixx>0.00822917</ixx>
                    <ixy>0</ixy>
                    <ixz>0</ixz>
                    <iyy>0.00822917</iyy>
                    <iyz>0</iyz>
                    <izz>0.015625</izz>
                </inertia>
            </inertial>
            <collision name='front_left_wheel_collision'>
                <pose>0 0 0 0 -0 0</pose>
                <geometry>
                    <cylinder>
                        <length>0.1</length>
                        <radius>0.25</radius>
                    </cylinder>
                </geometry>
                <surface>
                    <contact>
                        <ode/>
                    </contact>
                    <friction>
                        <ode/>
                    </friction>
                </surface>
            </collision>
            <visual name='front_left_wheel_visual'>
                <pose>0 0 0 0 -0 0</pose>
                <geometry>
                    <cylinder>
                        <length>0.1</length>
                        <radius>0.25</radius>
                    </cylinder>
                </geometry>
                <material>
                    <diffuse> 0.3 0.3 0.3 1 </diffuse>
                    <specular> 0 0.2 0.2 1  </specular>
                    <emissive> 0 0 0 1 </emissive>
                    <ambient> 0.1 0.1 0.1 1 </ambient>
                </material>
            </visual>
        </link>
        <!-- <joint name='right_wheel_joint' type='revolute'> -->
        <joint name='front_right_wheel_to_body' type='revolute'>
            <pose relative_to='car_body__link'>0.6 -0.5 -0.125 -1.5708 0 0</pose>
            <parent>car_body__link</parent>
            <child>front_right_wheel</child>
            <axis>
                <xyz>0 0 1</xyz>
                <limit>
                    <lower>-1e+16</lower>
                    <upper>1e+16</upper>
                </limit>
                <dynamics>
                    <damping>0</damping>
                    <friction>0.5</friction>
                    <spring_reference>0</spring_reference>
                    <spring_stiffness>0</spring_stiffness>
                </dynamics>
            </axis>
        </joint>
        <link name='front_right_wheel'>
            <pose relative_to='front_right_wheel_to_body'>0 0 0 0 -0 0</pose>
            <!-- <pose relative_to='right_wheel_joint'>0 0 0 0 -0 0</pose> -->
            <inertial>
                <pose>0 0 0 0 -0 0</pose>
                <mass>0.5</mass>
                <inertia>
                    <ixx>0.00822917</ixx>
                    <ixy>0</ixy>
                    <ixz>0</ixz>
                    <iyy>0.00822917</iyy>
                    <iyz>0</iyz>
                    <izz>0.015625</izz>
                </inertia>
            </inertial>
            <collision name='front_right_wheel_collision'>
                <pose>0 0 0 0 -0 0</pose>
                <geometry>
                    <cylinder>
                        <length>0.1</length>
                        <radius>0.25</radius>
                    </cylinder>
                </geometry>
                <surface>
                    <contact>
                        <ode/>
                    </contact>
                    <friction>
                        <ode/>
                    </friction>
                </surface>
            </collision>
            <visual name='front_right_wheel_visual'>
                <pose>0 0 0 0 -0 0</pose>
                <geometry>
                    <cylinder>
                        <length>0.1</length>
                        <radius>0.25</radius>
                    </cylinder>
                </geometry>
                <material>
                    <diffuse> 0.3 0.3 0.3 1 </diffuse>
                    <specular> 0 0.2 0.2 1  </specular>
                    <emissive> 0 0 0 1 </emissive>
                    <ambient> 0.1 0.1 0.1 1 </ambient>
                </material>
            </visual>
        </link>
        <joint name='rear_left_ball_wheel_to_body' type='ball'>
            <pose relative_to='car_body__link'>-0.6 0.3 -0.25 0 -0 0</pose>
            <parent>car_body__link</parent>
            <child>rear_left_ball_wheel</child>
        </joint>
        <link name='rear_left_ball_wheel'>
            <pose relative_to='rear_left_ball_wheel_to_body'>0 0 0 0 -0 0</pose>
            <inertial>
                <pose>0 0 0 0 -0 0</pose>
                <mass>0.5</mass>
                <inertia>
                    <ixx>0.003125</ixx>
                    <ixy>0</ixy>
                    <ixz>0</ixz>
                    <iyy>0.003125</iyy>
                    <iyz>0</iyz>
                    <izz>0.003125</izz>
                </inertia>
            </inertial>
            <collision name='rear_left_ball_wheel_collision'>
                <pose>0 0 0 0 -0 0</pose>
                <geometry>
                    <sphere>
                        <radius>0.125</radius>
                    </sphere>
                </geometry>
                <surface>
                    <contact>
                        <ode/>
                    </contact>
                    <friction>
                        <ode/>
                    </friction>
                </surface>
            </collision>
            <visual name='rear_left_ball_wheel_visual'>
                <pose>0 0 0 0 -0 0</pose>
                <geometry>
                    <sphere>
                        <radius>0.125</radius>
                    </sphere>
                </geometry>
                <material>
                    <diffuse> 0.3 0.3 0.3 1 </diffuse>
                    <specular> 0 0.2 0.2 1  </specular>
                    <emissive> 0 0 0 1 </emissive>
                    <ambient> 0.1 0.1 0.1 1 </ambient>
                </material>
            </visual>
        </link>
        <joint name='rear_right_ball_wheel_to_body' type='ball'>
            <pose relative_to='car_body__link'>-0.6 -0.3 -0.25 0 -0 0</pose>
            <parent>car_body__link</parent>
            <child>rear_right_ball_wheel</child>
        </joint>
        <link name='rear_right_ball_wheel'>
            <pose relative_to='rear_right_ball_wheel_to_body'>0 0 0 0 -0 0</pose>
            <inertial>
                <pose>0 0 0 0 -0 0</pose>
                <mass>0.5</mass>
                <inertia>
                    <ixx>0.003125</ixx>
                    <ixy>0</ixy>
                    <ixz>0</ixz>
                    <iyy>0.003125</iyy>
                    <iyz>0</iyz>
                    <izz>0.003125</izz>
                </inertia>
            </inertial>
            <collision name='rear_right_ball_wheel_collision'>
                <pose>0 0 0 0 -0 0</pose>
                <geometry>
                    <sphere>
                        <radius>0.125</radius>
                    </sphere>
                </geometry>
                <surface>
                    <contact>
                        <ode/>
                    </contact>
                    <friction>
                        <ode/>
                    </friction>
                </surface>
            </collision>
            <visual name='rear_right_ball_wheel_visual'>
                <pose>0 0 0 0 -0 0</pose>
                <geometry>
                    <sphere>
                        <radius>0.125</radius>
                    </sphere>
                </geometry>
                <material>
                    <diffuse> 0.3 0.3 0.3 1 </diffuse>
                    <specular> 0 0.2 0.2 1  </specular>
                    <emissive> 0 0 0 1 </emissive>
                    <ambient> 0.1 0.1 0.1 1 </ambient>
                </material>
            </visual>
        </link>
        <static>0</static>
        <plugin name='ignition::gazebo::systems::DiffDrive' filename='ignition-gazebo-diff-drive-system'>
            <left_joint>front_left_wheel_to_body</left_joint>
            <right_joint>front_right_wheel_to_body</right_joint>
            <wheel_separation>1</wheel_separation>
            <wheel_radius>0.25</wheel_radius>
            <odom_publish_frequency>1</odom_publish_frequency>
            <max_linear_acceleration>1</max_linear_acceleration>
            <min_linear_acceleration>-1</min_linear_acceleration>
            <max_angular_acceleration>1</max_angular_acceleration>
            <min_angular_acceleration>-1</min_angular_acceleration>
            <max_linear_velocity>0.5</max_linear_velocity>
            <min_linear_velocity>-0.5</min_linear_velocity>
            <max_angular_velocity>1</max_angular_velocity>
            <min_angular_velocity>-1</min_angular_velocity>
        </plugin>
        <plugin filename="libignition-gazebo-joint-state-publisher-system.so" name="ignition::gazebo::systems::JointStatePublisher ">
            <joint_name>front_right_wheel_to_body</joint_name>
            <joint_name>front_left_wheel_to_body</joint_name>
            <joint_name>rear_right_ball_wheel_to_body</joint_name>
            <joint_name>rear_left_ball_wheel_to_body</joint_name>
        </plugin>
    </model>
</sdf>
